<?xml version="1.0" encoding="UTF-8"?>
<testng-results ignored="0" total="1" passed="0" failed="1" skipped="0">
  <reporter-output>
  </reporter-output>
  <suite started-at="2023-06-21T12:25:13 IST" name="Default suite" finished-at="2023-06-21T12:25:13 IST" duration-ms="137">
    <groups>
    </groups>
    <test started-at="2023-06-21T12:25:13 IST" name="Default test" finished-at="2023-06-21T12:25:13 IST" duration-ms="137">
      <class name="TestNG.xdcx">
        <test-method signature="TC2()[pri:0, instance:TestNG.xdcx@515aebb0]" started-at="2023-06-21T12:25:13 IST" name="TC2" finished-at="2023-06-21T12:25:13 IST" duration-ms="36" status="FAIL">
          <exception class="java.lang.AssertionError">
            <message>
              <![CDATA[Failed: both results are same:   did not expect [hi] but found [hi]]]>
            </message>
            <full-stacktrace>
              <![CDATA[java.lang.AssertionError: Failed: both results are same:   did not expect [hi] but found [hi]
at org.testng.Assert.fail(Assert.java:111)
at org.testng.Assert.failEquals(Assert.java:1582)
at org.testng.Assert.assertNotEqualsImpl(Assert.java:157)
at org.testng.Assert.assertNotEquals(Assert.java:2198)
at TestNG.xdcx.TC2(xdcx.java:14)
at java.base/jdk.internal.reflect.NativeMethodAccessorImpl.invoke0(Native Method)
at java.base/jdk.internal.reflect.NativeMethodAccessorImpl.invoke(NativeMethodAccessorImpl.java:77)
at java.base/jdk.internal.reflect.DelegatingMethodAccessorImpl.invoke(DelegatingMethodAccessorImpl.java:43)
at java.base/java.lang.reflect.Method.invoke(Method.java:568)
at org.testng.internal.invokers.MethodInvocationHelper.invokeMethod(MethodInvocationHelper.java:139)
at org.testng.internal.invokers.TestInvoker.invokeMethod(TestInvoker.java:664)
at org.testng.internal.invokers.TestInvoker.invokeTestMethod(TestInvoker.java:227)
at org.testng.internal.invokers.MethodRunner.runInSequence(MethodRunner.java:50)
at org.testng.internal.invokers.TestInvoker$MethodInvocationAgent.invoke(TestInvoker.java:957)
at org.testng.internal.invokers.TestInvoker.invokeTestMethods(TestInvoker.java:200)
at org.testng.internal.invokers.TestMethodWorker.invokeTestMethods(TestMethodWorker.java:148)
at org.testng.internal.invokers.TestMethodWorker.run(TestMethodWorker.java:128)
at java.base/java.util.ArrayList.forEach(ArrayList.java:1511)
at org.testng.TestRunner.privateRun(TestRunner.java:848)
at org.testng.TestRunner.run(TestRunner.java:621)
at org.testng.SuiteRunner.runTest(SuiteRunner.java:443)
at org.testng.SuiteRunner.runSequentially(SuiteRunner.java:437)
at org.testng.SuiteRunner.privateRun(SuiteRunner.java:397)
at org.testng.SuiteRunner.run(SuiteRunner.java:336)
at org.testng.SuiteRunnerWorker.runSuite(SuiteRunnerWorker.java:52)
at org.testng.SuiteRunnerWorker.run(SuiteRunnerWorker.java:95)
at org.testng.TestNG.runSuitesSequentially(TestNG.java:1280)
at org.testng.TestNG.runSuitesLocally(TestNG.java:1200)
at org.testng.TestNG.runSuites(TestNG.java:1114)
at org.testng.TestNG.run(TestNG.java:1082)
at org.testng.remote.AbstractRemoteTestNG.run(AbstractRemoteTestNG.java:115)
at org.testng.remote.RemoteTestNG.initAndRun(RemoteTestNG.java:251)
at org.testng.remote.RemoteTestNG.main(RemoteTestNG.java:77)
]]>
            </full-stacktrace>
          </exception> <!-- java.lang.AssertionError -->
          <reporter-output>
          </reporter-output>
        </test-method> <!-- TC2 -->
      </class> <!-- TestNG.xdcx -->
    </test> <!-- Default test -->
  </suite> <!-- Default suite -->
</testng-results>
